#VRML_SIM R2022b utf8
# license: Apache License 2.0
# license url: http://www.apache.org/licenses/LICENSE-2.0
# This is a proto file for Webots for the Shuangzu
# Extracted from: /home/fugo/Downloads/shuangzu/urdf/shuangzu.urdf

PROTO Shuangzu [
  field  SFVec3f     translation     0 0 0
  field  SFRotation  rotation        0 0 1 0
  field  SFString    name            "Shuangzu"  # Is `Robot.name`.
  field  SFString    controller      "void"      # Is `Robot.controller`.
  field  MFString    controllerArgs  []          # Is `Robot.controllerArgs`.
  field  SFString    customData      ""          # Is `Robot.customData`.
  field  SFBool      supervisor      FALSE       # Is `Robot.supervisor`.
  field  SFBool      synchronization TRUE        # Is `Robot.synchronization`.
  field  SFBool      selfCollision   FALSE       # Is `Robot.selfCollision`.
]
{
  Robot {
    translation IS translation
    rotation IS rotation
    controller IS controller
    controllerArgs IS controllerArgs
    customData IS customData
    supervisor IS supervisor
    synchronization IS synchronization
    selfCollision IS selfCollision
    children [
      Shape {
        appearance DEF base_material PBRAppearance {
          baseColor 0.752941 0.752941 0.752941
          roughness 1.000000
          metalness 0
        }
        geometry DEF base Mesh {
          url "/home/fugo/Downloads/shuangzu/meshes/base.STL"
        }
      }
      Solid {
        translation -0.048000 -0.105000 -0.057500
        children [
          Shape {
            appearance DEF r1_material PBRAppearance {
              roughness 1.000000
              metalness 0
            }
            geometry DEF r1 Mesh {
              url "/home/fugo/Downloads/shuangzu/meshes/r1.STL"
            }
          }
          HingeJoint {
            jointParameters HingeJointParameters {
              axis -1.000000 0.000000 0.000000
            }
            device [
              RotationalMotor {
                name "r2"
                maxTorque 10000
              }
              PositionSensor {
                name "r2_sensor"
              }
            ]
            endPoint Solid {
              children [
                Shape {
                  appearance DEF r2_material PBRAppearance {
                    baseColor 0.752941 0.752941 0.752941
                    roughness 1.000000
                    metalness 0
                  }
                  geometry DEF r2 Mesh {
                    url "/home/fugo/Downloads/shuangzu/meshes/r2.STL"
                  }
                }
                HingeJoint {
                  jointParameters HingeJointParameters {
                    axis 0.000000 0.000000 1.000000
                    anchor 0.048000 0.000000 -0.041500
                  }
                  device [
                    RotationalMotor {
                      name "r3"
                      maxTorque 10000
                    }
                    PositionSensor {
                      name "r3_sensor"
                    }
                  ]
                  endPoint Solid {
                    translation 0.048000 0.000000 -0.041500
                    children [
                      Shape {
                        appearance DEF r3_material PBRAppearance {
                          baseColor 0.752941 0.752941 0.752941
                          roughness 1.000000
                          metalness 0
                        }
                        geometry DEF r3 Mesh {
                          url "/home/fugo/Downloads/shuangzu/meshes/r3.STL"
                        }
                      }
                      HingeJoint {
                        jointParameters HingeJointParameters {
                          axis 0.000000 1.000000 0.000000
                          anchor 0.000000 0.000000 -0.089000
                        }
                        device [
                          RotationalMotor {
                            name "r4"
                            maxTorque 10000
                          }
                          PositionSensor {
                            name "r4_sensor"
                          }
                        ]
                        endPoint Solid {
                          translation 0.000000 0.000000 -0.089000
                          children [
                            Shape {
                              appearance DEF r4_material PBRAppearance {
                                baseColor 0.752941 0.752941 0.752941
                                roughness 1.000000
                                metalness 0
                              }
                              geometry DEF r4 Mesh {
                                url "/home/fugo/Downloads/shuangzu/meshes/r4.STL"
                              }
                            }
                            HingeJoint {
                              jointParameters HingeJointParameters {
                                axis 0.000000 -1.000000 0.000000
                                anchor 0.000000 0.000000 -0.360000
                              }
                              device [
                                RotationalMotor {
                                  name "r5"
                                  maxTorque 10000
                                }
                                PositionSensor {
                                  name "r5_sensor"
                                }
                              ]
                              endPoint Solid {
                                translation 0.000000 0.000000 -0.360000
                                children [
                                  Shape {
                                    appearance DEF r5_material PBRAppearance {
                                      baseColor 0.752941 0.752941 0.752941
                                      roughness 1.000000
                                      metalness 0
                                    }
                                    geometry DEF r5 Mesh {
                                      url "/home/fugo/Downloads/shuangzu/meshes/r5.STL"
                                    }
                                  }
                                  HingeJoint {
                                    jointParameters HingeJointParameters {
                                      axis 0.000000 1.000000 0.000000
                                      anchor 0.000000 0.000000 -0.340000
                                    }
                                    device [
                                      RotationalMotor {
                                        name "r6"
                                        maxTorque 10000
                                      }
                                      PositionSensor {
                                        name "r6_sensor"
                                      }
                                    ]
                                    endPoint Solid {
                                      translation 0.000000 0.000000 -0.340000
                                      children [
                                        Shape {
                                          appearance DEF r6_material PBRAppearance {
                                            baseColor 0.752941 0.752941 0.752941
                                            roughness 1.000000
                                            metalness 0
                                          }
                                          geometry DEF r6 Mesh {
                                            url "/home/fugo/Downloads/shuangzu/meshes/r6.STL"
                                          }
                                        }
                                        HingeJoint {
                                          jointParameters HingeJointParameters {
                                          }
                                          device [
                                            RotationalMotor {
                                              name "r7"
                                              maxTorque 10000
                                            }
                                            PositionSensor {
                                              name "r7_sensor"
                                            }
                                          ]
                                          endPoint Solid {
                                            children [
                                              Shape {
                                                appearance DEF r7_material PBRAppearance {
                                                  baseColor 0.752941 0.752941 0.752941
                                                  roughness 1.000000
                                                  metalness 0
                                                }
                                                geometry DEF r7 Mesh {
                                                  url "/home/fugo/Downloads/shuangzu/meshes/r7.STL"
                                                }
                                              }
                                            ]
                                            name "r7"
                                            boundingObject USE r7
                                            physics Physics {
                                              density -1
                                              mass 0.165596
                                              centerOfMass [ 0.018446 -0.000000 -0.027780 ]
                                              inertiaMatrix [
                                                4.942578e-05 5.655364e-04 6.078228e-04
                                                1.409790e-09 1.449356e-05 -1.078665e-11
                                              ]
                                            }
                                          }
                                        }
                                      ]
                                      name "r6"
                                      boundingObject USE r6
                                      physics Physics {
                                        density -1
                                        mass 0.010379
                                        centerOfMass [ 0.000000 0.000000 -0.000000 ]
                                        inertiaMatrix [
                                          6.637953e-07 5.714335e-07 5.427969e-07
                                          -2.148788e-18 -7.479562e-15 3.383811e-15
                                        ]
                                      }
                                    }
                                  }
                                ]
                                name "r5"
                                boundingObject USE r5
                                physics Physics {
                                  density -1
                                  mass 0.279988
                                  centerOfMass [ 0.003777 0.000059 -0.120094 ]
                                  inertiaMatrix [
                                    3.149253e-03 3.204141e-03 1.529720e-04
                                    9.312980e-07 -1.151779e-05 1.230108e-06
                                  ]
                                }
                              }
                            }
                          ]
                          name "r4"
                          boundingObject USE r4
                          physics Physics {
                            density -1
                            mass 1.062088
                            centerOfMass [ 0.004143 0.014743 -0.116337 ]
                            inertiaMatrix [
                              9.218489e-03 1.106211e-02 2.174496e-03
                              -3.900747e-06 2.365663e-04 1.740349e-05
                            ]
                          }
                        }
                      }
                    ]
                    name "r3"
                    boundingObject USE r3
                    physics Physics {
                      density -1
                      mass 0.526481
                      centerOfMass [ -0.000754 -0.043614 -0.079545 ]
                      inertiaMatrix [
                        1.444363e-03 2.377690e-03 1.328525e-03
                        8.001201e-07 -4.524676e-07 -5.624336e-05
                      ]
                    }
                  }
                }
              ]
              name "r2"
              boundingObject USE r2
              physics Physics {
                density -1
                mass 0.326597
                centerOfMass [ 0.027139 0.000020 0.000943 ]
                inertiaMatrix [
                  3.344684e-04 2.247466e-04 2.979584e-04
                  1.699554e-08 8.590755e-06 -1.828168e-07
                ]
              }
            }
          }
        ]
        name "r1"
        boundingObject USE r1
        physics Physics {
          density -1
          mass 0.232041
          centerOfMass [ -0.030104 -0.000198 0.000052 ]
          inertiaMatrix [
            3.134264e-04 2.518518e-04 2.480381e-04
            -1.402350e-06 4.534508e-07 -5.336560e-08
          ]
        }
      }
      Solid {
        translation -0.048000 0.105000 -0.057500
        children [
          Shape {
            appearance DEF l1_material PBRAppearance {
              roughness 1.000000
              metalness 0
            }
            geometry DEF l1 Mesh {
              url "/home/fugo/Downloads/shuangzu/meshes/l1.STL"
            }
          }
          HingeJoint {
            jointParameters HingeJointParameters {
            }
            device [
              RotationalMotor {
                name "l2"
                maxTorque 10000
              }
              PositionSensor {
                name "l2_sensor"
              }
            ]
            endPoint Solid {
              children [
                Shape {
                  appearance DEF l2_material PBRAppearance {
                    baseColor 0.752941 0.752941 0.752941
                    roughness 1.000000
                    metalness 0
                  }
                  geometry DEF l2 Mesh {
                    url "/home/fugo/Downloads/shuangzu/meshes/l2.STL"
                  }
                }
                HingeJoint {
                  jointParameters HingeJointParameters {
                    axis 0.000000 0.000000 1.000000
                    anchor 0.048000 0.000000 -0.041500
                  }
                  device [
                    RotationalMotor {
                      name "l3"
                      maxTorque 10000
                    }
                    PositionSensor {
                      name "l3_sensor"
                    }
                  ]
                  endPoint Solid {
                    translation 0.048000 0.000000 -0.041500
                    children [
                      Shape {
                        appearance DEF l3_material PBRAppearance {
                          baseColor 0.752941 0.752941 0.752941
                          roughness 1.000000
                          metalness 0
                        }
                        geometry DEF l3 Mesh {
                          url "/home/fugo/Downloads/shuangzu/meshes/l3.STL"
                        }
                      }
                      HingeJoint {
                        jointParameters HingeJointParameters {
                          axis 0.000000 -1.000000 0.000000
                          anchor 0.000000 0.000000 -0.089000
                        }
                        device [
                          RotationalMotor {
                            name "l4"
                            maxTorque 10000
                          }
                          PositionSensor {
                            name "l4_sensor"
                          }
                        ]
                        endPoint Solid {
                          translation 0.000000 0.000000 -0.089000
                          children [
                            Shape {
                              appearance DEF l4_material PBRAppearance {
                                baseColor 0.752941 0.752941 0.752941
                                roughness 1.000000
                                metalness 0
                              }
                              geometry DEF l4 Mesh {
                                url "/home/fugo/Downloads/shuangzu/meshes/l4.STL"
                              }
                            }
                            HingeJoint {
                              jointParameters HingeJointParameters {
                                axis 0.000000 1.000000 0.000000
                                anchor 0.000000 0.000000 -0.360000
                              }
                              device [
                                RotationalMotor {
                                  name "l5"
                                  maxTorque 10000
                                }
                                PositionSensor {
                                  name "l5_sensor"
                                }
                              ]
                              endPoint Solid {
                                translation 0.000000 0.000000 -0.360000
                                children [
                                  Shape {
                                    appearance DEF l5_material PBRAppearance {
                                      baseColor 0.752941 0.752941 0.752941
                                      roughness 1.000000
                                      metalness 0
                                    }
                                    geometry DEF l5 Mesh {
                                      url "/home/fugo/Downloads/shuangzu/meshes/l5.STL"
                                    }
                                  }
                                  HingeJoint {
                                    jointParameters HingeJointParameters {
                                      axis 0.000000 1.000000 0.000000
                                      anchor 0.000000 0.000000 -0.340000
                                    }
                                    device [
                                      RotationalMotor {
                                        name "l6"
                                        maxTorque 10000
                                      }
                                      PositionSensor {
                                        name "l6_sensor"
                                      }
                                    ]
                                    endPoint Solid {
                                      translation 0.000000 0.000000 -0.340000
                                      children [
                                        Shape {
                                          appearance DEF l6_material PBRAppearance {
                                            baseColor 0.752941 0.752941 0.752941
                                            roughness 1.000000
                                            metalness 0
                                          }
                                          geometry DEF l6 Mesh {
                                            url "/home/fugo/Downloads/shuangzu/meshes/l6.STL"
                                          }
                                        }
                                        HingeJoint {
                                          jointParameters HingeJointParameters {
                                            axis -1.000000 0.000000 0.000000
                                          }
                                          device [
                                            RotationalMotor {
                                              name "l7"
                                              maxTorque 10000
                                            }
                                            PositionSensor {
                                              name "l7_sensor"
                                            }
                                          ]
                                          endPoint Solid {
                                            children [
                                              Shape {
                                                appearance DEF l7_material PBRAppearance {
                                                  baseColor 0.752941 0.752941 0.752941
                                                  roughness 1.000000
                                                  metalness 0
                                                }
                                                geometry DEF l7 Mesh {
                                                  url "/home/fugo/Downloads/shuangzu/meshes/l7.STL"
                                                }
                                              }
                                            ]
                                            name "l7"
                                            boundingObject USE l7
                                            physics Physics {
                                              density -1
                                              mass 0.165596
                                              centerOfMass [ 0.018446 -0.000000 -0.027780 ]
                                              inertiaMatrix [
                                                4.942578e-05 5.655364e-04 6.078228e-04
                                                1.409790e-09 1.449356e-05 -1.078665e-11
                                              ]
                                            }
                                          }
                                        }
                                      ]
                                      name "l6"
                                      boundingObject USE l6
                                      physics Physics {
                                        density -1
                                        mass 0.010433
                                        centerOfMass [ 0.000000 0.000000 -0.000000 ]
                                        inertiaMatrix [
                                          6.626256e-07 5.711108e-07 5.438955e-07
                                          -2.148737e-18 -7.479562e-15 3.383810e-15
                                        ]
                                      }
                                    }
                                  }
                                ]
                                name "l5"
                                boundingObject USE l5
                                physics Physics {
                                  density -1
                                  mass 0.279985
                                  centerOfMass [ 0.003776 -0.000059 -0.120094 ]
                                  inertiaMatrix [
                                    3.149225e-03 3.204112e-03 1.529715e-04
                                    -9.311083e-07 -1.151680e-05 -1.232901e-06
                                  ]
                                }
                              }
                            }
                          ]
                          name "l4"
                          boundingObject USE l4
                          physics Physics {
                            density -1
                            mass 1.062088
                            centerOfMass [ 0.004148 -0.014743 -0.115589 ]
                            inertiaMatrix [
                              9.218501e-03 1.106212e-02 2.174487e-03
                              3.889731e-06 2.371540e-04 -1.907486e-05
                            ]
                          }
                        }
                      }
                    ]
                    name "l3"
                    boundingObject USE l3
                    physics Physics {
                      density -1
                      mass 0.526481
                      centerOfMass [ 0.000704 0.043614 -0.079254 ]
                      inertiaMatrix [
                        1.440882e-03 2.377692e-03 1.332011e-03
                        6.212346e-07 7.990207e-06 5.653956e-05
                      ]
                    }
                  }
                }
              ]
              name "l2"
              boundingObject USE l2
              physics Physics {
                density -1
                mass 0.326597
                centerOfMass [ 0.027139 0.000020 0.000943 ]
                inertiaMatrix [
                  3.344684e-04 2.247466e-04 2.979584e-04
                  1.699612e-08 8.590755e-06 -1.828173e-07
                ]
              }
            }
          }
        ]
        name "l1"
        boundingObject USE l1
        physics Physics {
          density -1
          mass 0.232041
          centerOfMass [ -0.030104 0.000198 -0.000052 ]
          inertiaMatrix [
            3.134264e-04 2.518518e-04 2.480381e-04
            1.402350e-06 -4.534505e-07 -5.336537e-08
          ]
        }
      }
      HingeJoint {
        jointParameters HingeJointParameters {
          anchor 0.000000 0.000000 0.006500
        }
        device [
          RotationalMotor {
            name "y3"
            maxTorque 10000
          }
          PositionSensor {
            name "y3_sensor"
          }
        ]
        endPoint Solid {
          translation 0.000000 0.000000 0.006500
          children [
            Shape {
              appearance DEF y3_material PBRAppearance {
                baseColor 0.752941 0.752941 0.752941
                roughness 1.000000
                metalness 0
              }
              geometry DEF y3 Mesh {
                url "/home/fugo/Downloads/shuangzu/meshes/y3.STL"
              }
            }
            HingeJoint {
              jointParameters HingeJointParameters {
                axis 0.000000 -1.000000 0.000000
                anchor 0.000000 -0.039650 0.055000
              }
              device [
                RotationalMotor {
                  name "y2"
                  maxTorque 10000
                }
                PositionSensor {
                  name "y2_sensor"
                }
              ]
              endPoint Solid {
                translation 0.000000 -0.039650 0.055000
                children [
                  Shape {
                    appearance DEF y2_material PBRAppearance {
                      baseColor 0.752941 0.752941 0.752941
                      roughness 1.000000
                      metalness 0
                    }
                    geometry DEF y2 Mesh {
                      url "/home/fugo/Downloads/shuangzu/meshes/y2.STL"
                    }
                  }
                  HingeJoint {
                    jointParameters HingeJointParameters {
                      axis 0.000000 0.000000 -1.000000
                      anchor 0.000000 0.039650 -0.055000
                    }
                    device [
                      RotationalMotor {
                        name "y1"
                        maxTorque 10000
                      }
                      PositionSensor {
                        name "y1_sensor"
                      }
                    ]
                    endPoint Solid {
                      translation 0.000000 0.039650 -0.055000
                      children [
                        Shape {
                          appearance DEF y1_material PBRAppearance {
                            baseColor 0.752941 0.752941 0.752941
                            roughness 1.000000
                            metalness 0
                          }
                          geometry DEF y1 Mesh {
                            url "/home/fugo/Downloads/shuangzu/meshes/y1.STL"
                          }
                        }
                        Solid {
                          translation 0.000000 0.000000 0.337603
                          children [
                            Shape {
                              appearance DEF b1_material PBRAppearance {
                                baseColor 0.752941 0.752941 0.752941
                                roughness 1.000000
                                metalness 0
                              }
                              geometry DEF b1 Mesh {
                                url "/home/fugo/Downloads/shuangzu/meshes/b1.STL"
                              }
                            }
                            HingeJoint {
                              jointParameters HingeJointParameters {
                                axis 0.000012 0.000068 -1.000000
                                anchor 0.000000 0.000000 0.146926
                              }
                              device [
                                RotationalMotor {
                                  name "t2"
                                  maxTorque 10000
                                }
                                PositionSensor {
                                  name "t2_sensor"
                                }
                              ]
                              endPoint Solid {
                                translation 0.000000 0.000000 0.146926
                                children [
                                  Shape {
                                    appearance DEF t2_material PBRAppearance {
                                      baseColor 0.752941 0.752941 0.752941
                                      roughness 1.000000
                                      metalness 0
                                    }
                                    geometry DEF t2 Mesh {
                                      url "/home/fugo/Downloads/shuangzu/meshes/t2.STL"
                                    }
                                  }
                                  HingeJoint {
                                    jointParameters HingeJointParameters {
                                      axis 1.000000 0.000000 0.000012
                                      anchor -0.021401 0.000000 0.122500
                                    }
                                    device [
                                      RotationalMotor {
                                        name "t3"
                                        maxTorque 10000
                                      }
                                      PositionSensor {
                                        name "t3_sensor"
                                      }
                                    ]
                                    endPoint Solid {
                                      translation -0.021401 0.000000 0.122500
                                      children [
                                        Shape {
                                          appearance DEF t3_material PBRAppearance {
                                            baseColor 0.752941 0.752941 0.752941
                                            roughness 1.000000
                                            metalness 0
                                          }
                                          geometry DEF t3 Mesh {
                                            url "/home/fugo/Downloads/shuangzu/meshes/t3.STL"
                                          }
                                        }
                                        HingeJoint {
                                          jointParameters HingeJointParameters {
                                            axis 0.000000 -1.000000 -0.000069
                                            anchor 0.021400 -0.023000 0.000000
                                          }
                                          device [
                                            RotationalMotor {
                                              name "t4"
                                              maxTorque 10000
                                            }
                                            PositionSensor {
                                              name "t4_sensor"
                                            }
                                          ]
                                          endPoint Solid {
                                            translation 0.021400 -0.023000 0.000000
                                            children [
                                              Shape {
                                                appearance DEF t4_material PBRAppearance {
                                                  roughness 1.000000
                                                  metalness 0
                                                }
                                                geometry DEF t4 Mesh {
                                                  url "/home/fugo/Downloads/shuangzu/meshes/t4.STL"
                                                }
                                              }
                                            ]
                                            name "t4"
                                            boundingObject USE t4
                                            physics Physics {
                                              density -1
                                              mass 0.010626
                                              centerOfMass [ -0.000000 0.021081 0.018975 ]
                                              inertiaMatrix [
                                                7.504969e-06 3.569963e-06 5.491554e-06
                                                4.717857e-12 2.458348e-11 -3.866617e-07
                                              ]
                                            }
                                          }
                                        }
                                      ]
                                      name "t3"
                                      boundingObject USE t3
                                      physics Physics {
                                        density -1
                                        mass 0.018957
                                        centerOfMass [ 0.020860 0.002997 -0.001947 ]
                                        inertiaMatrix [
                                          3.072610e-06 5.660771e-06 3.718784e-06
                                          4.102925e-08 1.783123e-08 -1.517050e-08
                                        ]
                                      }
                                    }
                                  }
                                ]
                                name "t2"
                                boundingObject USE t2
                                physics Physics {
                                  density -1
                                  mass 0.071731
                                  centerOfMass [ 0.001296 -0.000007 0.056236 ]
                                  inertiaMatrix [
                                    4.733537e-05 5.073640e-05 2.892616e-05
                                    -5.918076e-09 -6.334510e-06 -3.001181e-08
                                  ]
                                }
                              }
                            }
                            HingeJoint {
                              jointParameters HingeJointParameters {
                                axis 0.000000 -0.906308 0.422618
                                anchor 0.000000 -0.126624 0.019656
                              }
                              device [
                                RotationalMotor {
                                  name "you1"
                                  maxTorque 10000
                                }
                                PositionSensor {
                                  name "you1_sensor"
                                }
                              ]
                              endPoint Solid {
                                translation 0.000000 -0.126624 0.019656
                                rotation -1.000000 0.000000 0.000000 0.436332
                                children [
                                  Shape {
                                    appearance DEF you1_material PBRAppearance {
                                      baseColor 0.752941 0.752941 0.752941
                                      roughness 1.000000
                                      metalness 0
                                    }
                                    geometry DEF you1 Mesh {
                                      url "/home/fugo/Downloads/shuangzu/meshes/you1.STL"
                                    }
                                  }
                                  HingeJoint {
                                    jointParameters HingeJointParameters {
                                      axis -1.000000 -0.000000 0.000000
                                      anchor 0.032000 -0.067000 0.000000
                                    }
                                    device [
                                      RotationalMotor {
                                        name "you2"
                                        maxTorque 10000
                                      }
                                      PositionSensor {
                                        name "you2_sensor"
                                      }
                                    ]
                                    endPoint Solid {
                                      translation 0.032000 -0.067000 0.000000
                                      rotation 1.000000 0.000000 0.000000 2.007129
                                      children [
                                        Shape {
                                          appearance DEF you2_material PBRAppearance {
                                            baseColor 0.752941 0.752941 0.752941
                                            roughness 1.000000
                                            metalness 0
                                          }
                                          geometry DEF you2 Mesh {
                                            url "/home/fugo/Downloads/shuangzu/meshes/you2.STL"
                                          }
                                        }
                                        HingeJoint {
                                          jointParameters HingeJointParameters {
                                            axis 0.000000 -1.000000 0.000000
                                            anchor -0.032000 -0.136530 0.040000
                                          }
                                          device [
                                            RotationalMotor {
                                              name "you3"
                                              maxTorque 10000
                                            }
                                            PositionSensor {
                                              name "you3_sensor"
                                            }
                                          ]
                                          endPoint Solid {
                                            translation -0.032000 -0.136530 0.040000
                                            children [
                                              Shape {
                                                appearance DEF you3_material PBRAppearance {
                                                  baseColor 0.752941 0.752941 0.752941
                                                  roughness 1.000000
                                                  metalness 0
                                                }
                                                geometry DEF you3 Mesh {
                                                  url "/home/fugo/Downloads/shuangzu/meshes/you3.STL"
                                                }
                                              }
                                              HingeJoint {
                                                jointParameters HingeJointParameters {
                                                  axis 0.000000 0.000000 1.000000
                                                  anchor 0.000000 -0.110000 0.022530
                                                }
                                                device [
                                                  RotationalMotor {
                                                    name "you4"
                                                    maxTorque 10000
                                                  }
                                                  PositionSensor {
                                                    name "you4_sensor"
                                                  }
                                                ]
                                                endPoint Solid {
                                                  translation 0.000000 -0.110000 0.022530
                                                  children [
                                                    Shape {
                                                      appearance DEF you4_material PBRAppearance {
                                                        baseColor 0.752941 0.752941 0.752941
                                                        roughness 1.000000
                                                        metalness 0
                                                      }
                                                      geometry DEF you4 Mesh {
                                                        url "/home/fugo/Downloads/shuangzu/meshes/you4.STL"
                                                      }
                                                    }
                                                    HingeJoint {
                                                      jointParameters HingeJointParameters {
                                                        axis -0.000069 1.000000 0.000000
                                                        anchor 0.000000 -0.119030 -0.022500
                                                      }
                                                      device [
                                                        RotationalMotor {
                                                          name "you5"
                                                          maxTorque 10000
                                                        }
                                                        PositionSensor {
                                                          name "you5_sensor"
                                                        }
                                                      ]
                                                      endPoint Solid {
                                                        translation 0.000000 -0.119030 -0.022500
                                                        rotation 0.000000 0.000000 1.000000 0.000069
                                                        children [
                                                          Shape {
                                                            appearance DEF you5_material PBRAppearance {
                                                              baseColor 0.752941 0.752941 0.752941
                                                              roughness 1.000000
                                                              metalness 0
                                                            }
                                                            geometry DEF you5 Mesh {
                                                              url "/home/fugo/Downloads/shuangzu/meshes/you5.STL"
                                                            }
                                                          }
                                                          HingeJoint {
                                                            jointParameters HingeJointParameters {
                                                              axis 0.000000 0.000000 -1.000000
                                                              anchor 0.000000 -0.122500 0.021400
                                                            }
                                                            device [
                                                              RotationalMotor {
                                                                name "you6"
                                                                maxTorque 10000
                                                              }
                                                              PositionSensor {
                                                                name "you6_sensor"
                                                              }
                                                            ]
                                                            endPoint Solid {
                                                              translation 0.000000 -0.122500 0.021400
                                                              children [
                                                                Shape {
                                                                  appearance DEF you6_material PBRAppearance {
                                                                    baseColor 0.752941 0.752941 0.752941
                                                                    roughness 1.000000
                                                                    metalness 0
                                                                  }
                                                                  geometry DEF you6 Mesh {
                                                                    url "/home/fugo/Downloads/shuangzu/meshes/you6.STL"
                                                                  }
                                                                }
                                                                HingeJoint {
                                                                  jointParameters HingeJointParameters {
                                                                    axis -1.000000 0.000000 0.000000
                                                                    anchor -0.023000 0.000000 -0.021400
                                                                  }
                                                                  device [
                                                                    RotationalMotor {
                                                                      name "you7"
                                                                      maxTorque 10000
                                                                    }
                                                                    PositionSensor {
                                                                      name "you7_sensor"
                                                                    }
                                                                  ]
                                                                  endPoint Solid {
                                                                    translation -0.023000 0.000000 -0.021400
                                                                    children [
                                                                      Shape {
                                                                        appearance DEF you7_material PBRAppearance {
                                                                          roughness 1.000000
                                                                          metalness 0
                                                                        }
                                                                        geometry DEF you7 Mesh {
                                                                          url "/home/fugo/Downloads/shuangzu/meshes/you7.STL"
                                                                        }
                                                                      }
                                                                    ]
                                                                    name "you7"
                                                                    boundingObject USE you7
                                                                    physics Physics {
                                                                      density -1
                                                                      mass 0.010626
                                                                      centerOfMass [ 0.021083 -0.018973 -0.000000 ]
                                                                      inertiaMatrix [
                                                                        3.569910e-06 5.491607e-06 7.504969e-06
                                                                        3.865301e-07 3.284206e-15 -3.225981e-16
                                                                      ]
                                                                    }
                                                                  }
                                                                }
                                                              ]
                                                              name "you6"
                                                              boundingObject USE you6
                                                              physics Physics {
                                                                density -1
                                                                mass 0.018957
                                                                centerOfMass [ 0.002997 0.001947 -0.020860 ]
                                                                inertiaMatrix [
                                                                  5.660766e-06 3.718783e-06 3.072610e-06
                                                                  1.530428e-08 -4.102918e-08 1.783754e-08
                                                                ]
                                                              }
                                                            }
                                                          }
                                                        ]
                                                        name "you5"
                                                        boundingObject USE you5
                                                        physics Physics {
                                                          density -1
                                                          mass 0.071730
                                                          centerOfMass [ -0.000003 -0.056236 -0.001297 ]
                                                          inertiaMatrix [
                                                            5.073622e-05 2.892606e-05 4.733507e-05
                                                            3.152759e-08 6.326881e-09 -6.334711e-06
                                                          ]
                                                        }
                                                      }
                                                    }
                                                  ]
                                                  name "you4"
                                                  boundingObject USE you4
                                                  physics Physics {
                                                    density -1
                                                    mass 0.081800
                                                    centerOfMass [ -0.000047 -0.077743 -0.019141 ]
                                                    inertiaMatrix [
                                                      4.047475e-05 3.748727e-05 3.697512e-05
                                                      -4.637101e-08 1.063402e-08 -9.620553e-07
                                                    ]
                                                  }
                                                }
                                              }
                                            ]
                                            name "you3"
                                            boundingObject USE you3
                                            physics Physics {
                                              density -1
                                              mass 0.090241
                                              centerOfMass [ -0.001215 -0.064493 0.000429 ]
                                              inertiaMatrix [
                                                3.609312e-05 2.654242e-05 4.243317e-05
                                                -1.602211e-06 2.726051e-07 3.719024e-07
                                              ]
                                            }
                                          }
                                        }
                                      ]
                                      name "you2"
                                      boundingObject USE you2
                                      physics Physics {
                                        density -1
                                        mass 0.104284
                                        centerOfMass [ -0.021528 -0.079026 0.032906 ]
                                        inertiaMatrix [
                                          8.406889e-05 6.160202e-05 7.031370e-05
                                          -1.192774e-05 7.004518e-06 1.785496e-05
                                        ]
                                      }
                                    }
                                  }
                                ]
                                name "you1"
                                boundingObject USE you1
                                physics Physics {
                                  density -1
                                  mass 0.138901
                                  centerOfMass [ 0.003670 -0.048867 0.000108 ]
                                  inertiaMatrix [
                                    1.038089e-04 6.525371e-05 7.018980e-05
                                    -8.198696e-07 -3.521229e-09 -1.923526e-07
                                  ]
                                }
                              }
                            }
                            HingeJoint {
                              jointParameters HingeJointParameters {
                                axis 0.000000 0.906308 0.422618
                                anchor 0.000000 0.126624 0.019656
                              }
                              device [
                                RotationalMotor {
                                  name "zuo1"
                                  maxTorque 10000
                                }
                                PositionSensor {
                                  name "zuo1_sensor"
                                }
                              ]
                              endPoint Solid {
                                translation 0.000000 0.126624 0.019656
                                rotation 1.000000 0.000000 0.000000 0.436332
                                children [
                                  Shape {
                                    appearance DEF zuo1_material PBRAppearance {
                                      baseColor 0.752941 0.752941 0.752941
                                      roughness 1.000000
                                      metalness 0
                                    }
                                    geometry DEF zuo1 Mesh {
                                      url "/home/fugo/Downloads/shuangzu/meshes/zuo1.STL"
                                    }
                                  }
                                  HingeJoint {
                                    jointParameters HingeJointParameters {
                                      axis 1.000000 0.000000 -0.000000
                                      anchor 0.032000 0.067000 0.000000
                                    }
                                    device [
                                      RotationalMotor {
                                        name "zuo2"
                                        maxTorque 10000
                                      }
                                      PositionSensor {
                                        name "zuo2_sensor"
                                      }
                                    ]
                                    endPoint Solid {
                                      translation 0.032000 0.067000 0.000000
                                      rotation -1.000000 0.000000 0.000000 2.007129
                                      children [
                                        Shape {
                                          appearance DEF zuo2_material PBRAppearance {
                                            baseColor 0.752941 0.752941 0.752941
                                            roughness 1.000000
                                            metalness 0
                                          }
                                          geometry DEF zuo2 Mesh {
                                            url "/home/fugo/Downloads/shuangzu/meshes/zuo2.STL"
                                          }
                                        }
                                        HingeJoint {
                                          jointParameters HingeJointParameters {
                                            axis 0.000000 -1.000000 0.000000
                                            anchor -0.032000 0.136530 0.040000
                                          }
                                          device [
                                            RotationalMotor {
                                              name "zuo3"
                                              maxTorque 10000
                                            }
                                            PositionSensor {
                                              name "zuo3_sensor"
                                            }
                                          ]
                                          endPoint Solid {
                                            translation -0.032000 0.136530 0.040000
                                            children [
                                              Shape {
                                                appearance DEF zuo3_material PBRAppearance {
                                                  baseColor 0.752941 0.752941 0.752941
                                                  roughness 1.000000
                                                  metalness 0
                                                }
                                                geometry DEF zuo3 Mesh {
                                                  url "/home/fugo/Downloads/shuangzu/meshes/zuo3.STL"
                                                }
                                              }
                                              HingeJoint {
                                                jointParameters HingeJointParameters {
                                                  axis 0.000000 0.000000 1.000000
                                                  anchor 0.000000 0.110000 0.022530
                                                }
                                                device [
                                                  RotationalMotor {
                                                    name "zuo4"
                                                    maxTorque 10000
                                                  }
                                                  PositionSensor {
                                                    name "zuo4_sensor"
                                                  }
                                                ]
                                                endPoint Solid {
                                                  translation 0.000000 0.110000 0.022530
                                                  children [
                                                    Shape {
                                                      appearance DEF zuo4_material PBRAppearance {
                                                        baseColor 0.752941 0.752941 0.752941
                                                        roughness 1.000000
                                                        metalness 0
                                                      }
                                                      geometry DEF zuo4 Mesh {
                                                        url "/home/fugo/Downloads/shuangzu/meshes/zuo4.STL"
                                                      }
                                                    }
                                                    HingeJoint {
                                                      jointParameters HingeJointParameters {
                                                        axis 0.000070 -1.000000 0.000000
                                                        anchor 0.000000 0.119030 -0.022500
                                                      }
                                                      device [
                                                        RotationalMotor {
                                                          name "zuo5"
                                                          maxTorque 10000
                                                        }
                                                        PositionSensor {
                                                          name "zuo5_sensor"
                                                        }
                                                      ]
                                                      endPoint Solid {
                                                        translation 0.000000 0.119030 -0.022500
                                                        rotation 0.000000 0.000000 1.000000 0.000070
                                                        children [
                                                          Shape {
                                                            appearance DEF zuo5_material PBRAppearance {
                                                              baseColor 0.752941 0.752941 0.752941
                                                              roughness 1.000000
                                                              metalness 0
                                                            }
                                                            geometry DEF zuo5 Mesh {
                                                              url "/home/fugo/Downloads/shuangzu/meshes/zuo5.STL"
                                                            }
                                                          }
                                                          HingeJoint {
                                                            jointParameters HingeJointParameters {
                                                              axis 0.000000 0.000000 -1.000000
                                                              anchor 0.000000 0.122500 0.021400
                                                            }
                                                            device [
                                                              RotationalMotor {
                                                                name "zuo6"
                                                                maxTorque 10000
                                                              }
                                                              PositionSensor {
                                                                name "zuo6_sensor"
                                                              }
                                                            ]
                                                            endPoint Solid {
                                                              translation 0.000000 0.122500 0.021400
                                                              rotation 0.000000 0.000000 1.000000 0.000069
                                                              children [
                                                                Shape {
                                                                  appearance DEF zuo6_material PBRAppearance {
                                                                    baseColor 0.752941 0.752941 0.752941
                                                                    roughness 1.000000
                                                                    metalness 0
                                                                  }
                                                                  geometry DEF zuo6 Mesh {
                                                                    url "/home/fugo/Downloads/shuangzu/meshes/zuo6.STL"
                                                                  }
                                                                }
                                                                HingeJoint {
                                                                  jointParameters HingeJointParameters {
                                                                    axis 1.000000 0.000069 0.000000
                                                                    anchor 0.023000 0.000000 -0.021400
                                                                  }
                                                                  device [
                                                                    RotationalMotor {
                                                                      name "zuo7"
                                                                      maxTorque 10000
                                                                    }
                                                                    PositionSensor {
                                                                      name "zuo7_sensor"
                                                                    }
                                                                  ]
                                                                  endPoint Solid {
                                                                    translation 0.023000 0.000000 -0.021400
                                                                    rotation 0.000000 0.000000 1.000000 0.000069
                                                                    children [
                                                                      Shape {
                                                                        appearance DEF zuo7_material PBRAppearance {
                                                                          roughness 1.000000
                                                                          metalness 0
                                                                        }
                                                                        geometry DEF zuo7 Mesh {
                                                                          url "/home/fugo/Downloads/shuangzu/meshes/zuo7.STL"
                                                                        }
                                                                      }
                                                                    ]
                                                                    name "zuo7"
                                                                    boundingObject USE zuo7
                                                                    physics Physics {
                                                                      density -1
                                                                      mass 0.010626
                                                                      centerOfMass [ -0.021083 0.018973 -0.000000 ]
                                                                      inertiaMatrix [
                                                                        3.569910e-06 5.491607e-06 7.504969e-06
                                                                        3.865301e-07 -1.349160e-12 1.325243e-13
                                                                      ]
                                                                    }
                                                                  }
                                                                }
                                                              ]
                                                              name "zuo6"
                                                              boundingObject USE zuo6
                                                              physics Physics {
                                                                density -1
                                                                mass 0.018907
                                                                centerOfMass [ -0.002961 -0.001947 -0.020814 ]
                                                                inertiaMatrix [
                                                                  5.660366e-06 3.718732e-06 3.072202e-06
                                                                  1.543474e-08 4.102566e-08 -1.783421e-08
                                                                ]
                                                              }
                                                            }
                                                          }
                                                        ]
                                                        name "zuo5"
                                                        boundingObject USE zuo5
                                                        physics Physics {
                                                          density -1
                                                          mass 0.069365
                                                          centerOfMass [ -0.000009 0.056535 -0.002044 ]
                                                          inertiaMatrix [
                                                            5.056894e-05 2.868460e-05 4.693586e-05
                                                            3.152591e-08 -6.320898e-09 6.334707e-06
                                                          ]
                                                        }
                                                      }
                                                    }
                                                  ]
                                                  name "zuo4"
                                                  boundingObject USE zuo4
                                                  physics Physics {
                                                    density -1
                                                    mass 0.081800
                                                    centerOfMass [ -0.000047 0.077743 -0.019141 ]
                                                    inertiaMatrix [
                                                      4.047477e-05 3.748727e-05 3.697510e-05
                                                      4.618276e-08 1.062983e-08 9.620552e-07
                                                    ]
                                                  }
                                                }
                                              }
                                            ]
                                            name "zuo3"
                                            boundingObject USE zuo3
                                            physics Physics {
                                              density -1
                                              mass 0.092985
                                              centerOfMass [ -0.001180 0.065837 0.000843 ]
                                              inertiaMatrix [
                                                3.648807e-05 2.694774e-05 4.321004e-05
                                                1.600386e-06 2.722475e-07 -3.705850e-07
                                              ]
                                            }
                                          }
                                        }
                                      ]
                                      name "zuo2"
                                      boundingObject USE zuo2
                                      physics Physics {
                                        density -1
                                        mass 0.097621
                                        centerOfMass [ -0.020747 0.075097 0.032422 ]
                                        inertiaMatrix [
                                          8.197299e-05 5.724151e-05 6.800952e-05
                                          1.189612e-05 7.004663e-06 -1.785529e-05
                                        ]
                                      }
                                    }
                                  }
                                ]
                                name "zuo1"
                                boundingObject USE zuo1
                                physics Physics {
                                  density -1
                                  mass 0.138901
                                  centerOfMass [ 0.003670 0.048867 0.000108 ]
                                  inertiaMatrix [
                                    1.038087e-04 6.525312e-05 7.019017e-05
                                    8.198743e-07 -3.547595e-09 1.921135e-07
                                  ]
                                }
                              }
                            }
                          ]
                          name "b1"
                          boundingObject USE b1
                          physics Physics {
                            density -1
                            mass 1.248767
                            centerOfMass [ 0.000008 -0.000003 -0.025787 ]
                            inertiaMatrix [
                              7.028294e-03 4.647677e-03 2.605076e-03
                              -1.060029e-08 2.795733e-07 4.717556e-08
                            ]
                          }
                        }
                      ]
                      name "y1"
                      boundingObject USE y1
                      physics Physics {
                        density -1
                        mass 0.317200
                        centerOfMass [ 0.003766 0.000000 0.172200 ]
                        inertiaMatrix [
                          2.883540e-04 1.476436e-04 2.917480e-04
                          -3.091837e-10 -4.903642e-06 -5.493707e-11
                        ]
                      }
                    }
                  }
                ]
                name "y2"
                boundingObject USE y2
                physics Physics {
                  density -1
                  mass 1.066514
                  centerOfMass [ 0.000731 0.038922 0.042474 ]
                  inertiaMatrix [
                    1.709208e-03 1.709209e-03 9.492303e-04
                    -9.539366e-07 -2.296834e-05 -2.231903e-05
                  ]
                }
              }
            }
          ]
          name "y3"
          boundingObject USE y3
          physics Physics {
            density -1
            mass 0.378860
            centerOfMass [ -0.010388 -0.001695 0.022471 ]
            inertiaMatrix [
              1.969203e-04 3.549922e-04 3.836753e-04
              2.299471e-08 2.570038e-05 2.184391e-09
            ]
          }
        }
      }
    ]
    name IS name
    boundingObject USE base
    physics Physics {
      density -1
      mass 1.157133
      centerOfMass [ -0.038817 0.000012 -0.036001 ]
      inertiaMatrix [
        5.098696e-03 1.183534e-03 4.549600e-03
        -1.470590e-07 -3.596834e-05 3.218152e-07
      ]
    }
  }
}
